Workbook
Name monthly_target: README!$B$2
Name Selected_Month: Dashboard_product!$M$2
Name Selected_Month: Dashboard!$M$2
Name Producto: Dashboard_product!$N$2
Name Upper_Limit: README!$D$2
Name Lower_Limit: README!$C$2
Name Upper_percentile: README!$C$6
Name Product_month: product_summary!$M$2
Name Lower_percentile: README!$C$5
Name SlicerCache_Table_1_Col_4: #N/A

Sheet README
B1: Meta mensual | C1: Lower Limit | D1: Upper Limit
B2: 1000 | C2: 0 | D2: 5000
A5: Lower Limit | B5: 0.01 | C5: =PERCENTILE(product_summary!$F:$F, B5) -> 2.0866231
A6: Upper Limit | B6: 0.99 | C6: =PERCENTILE(product_summary!$F:$F, B6) -> 2783.2346

Sheet Sample - Superstore
A1: Row ID | B1: Order ID | C1: Order Date | D1: Ship Date | E1: Ship Mode | F1: Customer ID | G1: Customer Name | H1: Segment | I1: Country | J1: City | K1: State | L1: Postal Code | M1: Region | N1: Product ID | O1: Category | P1: Sub-Category | Q1: , | R1: Sales | S1: Quantity | T1: Discount | U1: Profit | V1: Month
A2: 1 | B2: CA-2016-160304 | C2: 42371 | D2: 42376 | E2: Standard Class | F2: BM-11575 | G2: Brendan Murry | H2: Corporate | I2: United States | J2: Gaithersburg | K2: Maryland | L2: 20877 | M2: East | N2: FUR-BO-10004709 | O2: Furniture | P2: Bookcases | Q2: Bush Westfield Collection Bookcases, Medium Cherry Finish | R2: 174.01158 | S2: 3 | T2: 0 | U2: 38.282548 | V2: =TEXT(C2,"yyyy-mm") -> 2016-01
A3: 2 | B3: CA-2016-160304 | C3: 42371 | D3: 42376 | E3: Standard Class | F3: BM-11575 | G3: Brendan Murry | H3: Corporate | I3: United States | J3: Gaithersburg | K3: Maryland | L3: 20877 | M3: East | N3: TEC-PH-10000455 | O3: Technology | P3: Phones | Q3: GE 30522EE2 | R3: 232.07547 | S3: 2 | T3: 0 | U3: 67.301885 | V3: =TEXT(C3,"yyyy-mm") -> 2016-01
A4: 3 | B4: CA-2016-125206 | C4: 42372 | D4: 42374 | E4: First Class | F4: LR-16915 | G4: Lena Radford | H4: Consumer | I4: United States | J4: Los Angeles | K4: California | L4: 90045 | M4: West | N4: OFF-ST-10003692 | O4: Office Supplies | P4: Storage | Q4: Recycled Steel Personal File for Hanging File Folders | R4: 114.46 | S4: 2 | T4: 0 | U4: 28.615 | V4: =TEXT(C4,"yyyy-mm") -> 2016-01
A5: 4 | B5: US-2016-116365 | C5: 42372 | D5: 42377 | E5: Standard Class | F5: CA-12310 | G5: Christine Abelman | H5: Corporate | I5: United States | J5: San Antonio | K5: Texas | L5: 78207 | M5: Central | N5: TEC-AC-10002217 | O5: Technology | P5: Accessories | Q5: ImationÂ Clip USBÂ flash driveÂ - 8 GB | R5: 30.104757 | S5: 2 | T5: 0.2 | U5: -5.2683325 | V5: =TEXT(C5,"yyyy-mm") -> 2016-01
A6: 5 | B6: US-2016-116365 | C6: 42372 | D6: 42377 | E6: Standard Class | F6: CA-12310 | G6: Christine Abelman | H6: Corporate | I6: United States | J6: San Antonio | K6: Texas | L6: 78207 | M6: Central | N6: TEC-AC-10002942 | O6: Technology | P6: Accessories | Q6: WD My Passport Ultra 1TB Portable External Hard Drive | R6: 165.7363 | S6: 3 | T6: 0.2 | U6: -6.2151111 | V6: =TEXT(C6,"yyyy-mm") -> 2016-01
A7: 6 | B7: US-2016-116365 | C7: 42372 | D7: 42377 | E7: Standard Class | F7: CA-12310 | G7: Christine Abelman | H7: Corporate | I7: United States | J7: San Antonio | K7: Texas | L7: 78207 | M7: Central | N7: TEC-PH-10002890 | O7: Technology | P7: Phones | Q7: AT&T 17929 Lendline Telephone | R7: 181.10894 | S7: 5 | T7: 0.2 | U7: 13.58317 | V7: =TEXT(C7,"yyyy-mm") -> 2016-01
A8: 7 | B8: CA-2016-105207 | C8: 42372 | D8: 42377 | E8: Standard Class | F8: BO-11350 | G8: Bill Overfelt | H8: Corporate | I8: United States | J8: Broken Arrow | K8: Oklahoma | L8: 74012 | M8: Central | N8: FUR-TA-10000617 | O8: Furniture | P8: Tables | Q8: Hon Practical Foundations 30 x 60 Training Table, Light Gray/Charcoal | R8: 1594.161 | S8: 7 | T8: 0 | U8: 350.71542 | V8: =TEXT(C8,"yyyy-mm") -> 2016-01
A9: 8 | B9: CA-2016-105207 | C9: 42372 | D9: 42377 | E9: Standard Class | F9: BO-11350 | G9: Bill Overfelt | H9: Corporate | I9: United States | J9: Broken Arrow | K9: Oklahoma | L9: 74012 | M9: Central | N9: OFF-BI-10004364 | O9: Office Supplies | P9: Binders | Q9: Storex Dura Pro Binders | R9: 11.889778 | S9: 2 | T9: 0 | U9: 5.3504 | V9: =TEXT(C9,"yyyy-mm") -> 2016-01
A10: 9 | B10: US-2016-164630 | C10: 42373 | D10: 42378 | E10: Standard Class | F10: EB-13975 | G10: Erica Bern | H10: Corporate | I10: United States | J10: Charlotte | K10: North Carolina | L10: 28205 | M10: South | N10: TEC-CO-10000971 | O10: Technology | P10: Copiers | Q10: Hewlett Packard 310 Color Digital Copier | R10: 800.5794 | S10: 4 | T10: 0.2 | U10: 100.07243 | V10: =TEXT(C10,"yyyy-mm") -> 2016-01
A11: 10 | B11: CA-2016-158211 | C11: 42373 | D11: 42377 | E11: Standard Class | F11: BP-11185 | G11: Ben Peterman | H11: Corporate | I11: United States | J11: Philadelphia | K11: Pennsylvania | L11: 19143 | M11: East | N11: OFF-AR-10004078 | O11: Office Supplies | P11: Art | Q11: Newell 312 | R11: 4.6777679 | S11: 1 | T11: 0.2 | U11: 0.58472099 | V11: =TEXT(C11,"yyyy-mm") -> 2016-01
A12: 11 | B12: CA-2016-158211 | C12: 42373 | D12: 42377 | E12: Standard Class | F12: BP-11185 | G12: Ben Peterman | H12: Corporate | I12: United States | J12: Philadelphia | K12: Pennsylvania | L12: 19143 | M12: East | N12: OFF-BI-10002026 | O12: Office Supplies | P12: Binders | Q12: Avery Arch Ring Binders | R12: 104.70911 | S12: 6 | T12: 0.7 | U12: -80.276985 | V12: =TEXT(C12,"yyyy-mm") -> 2016-01
A13: 12 | B13: CA-2016-134474 | C13: 42374 | D13: 42376 | E13: Second Class | F13: AJ-10795 | G13: Anthony Johnson | H13: Corporate | I13: United States | J13: Jacksonville | K13: Florida | L13: 32216 | M13: South | N13: TEC-AC-10001714 | O13: Technology | P13: Accessories | Q13: LogitechÂ MX Performance Wireless Mouse | R13: 161.26514 | S13: 6 | T13: 0.2 | U13: 34.268843 | V13: =TEXT(C13,"yyyy-mm") -> 2016-01
... A5900: 5899 | B5900: CA-2017-156720 | C5900: 43099 | D5900: 43103 | E5900: Standard Class | F5900: JM-15580 | G5900: Jill Matthias | H5900: Consumer | I5900: United States | J5900: Loveland | K5900: Colorado | L5900: 80538 | M5900: West | N5900: OFF-FA-10003472 | O5900: Office Supplies | P5900: Fasteners | Q5900: Bagged Rubber Bands | R5900: 3.024 | S5900: 3 | T5900: 0.2 | U5900: -0.6048 | V5900: =TEXT(C5900,"yyyy-mm") -> 2017-12

Sheet Dashboard
A1: SALES USD | E1: Profit | I1: Avance | M1: Mes
A2: =SUMIFS('Sample - Superstore'!$R:$R,'Sample - Superstore'!$V:$V,Selected_Month) -> 80524.656 | E2: =SUMIFS('Sample - Superstore'!$U:$U,'Sample - Superstore'!$V:$V,Selected_Month) -> 2762.3441 | I2: =IFERROR(SUMIFS('Sample - Superstore'!$R:$R,'Sample - Superstore'!$V:$V,Selected_Month)/monthly_target,0) -> 80.524656 | M2: 2016-11
A3: =IFERROR(__xludf.DUMMYFUNCTION("SPARKLINE(FILTER('Sample - Superstore'!R:R,TEXT('Sample - Superstore'!V:V,""yyyymm"")=TEXT(Selected_Month,""yyyymm""))) "),"") | C3: =IF(A2>=1,"OK","ALERTA") -> OK | E3: =IFERROR(__xludf.DUMMYFUNCTION("SPARKLINE(FILTER('Sample - Superstore'!$U:$U,'Sample - Superstore'!$V:$V<=Selected_Month))"),"") | G3: =IF(E2>=1,"OK","ALERTA") -> OK | I3: =IFERROR(__xludf.DUMMYFUNCTION("SPARKLINE(ARRAYFORMULA('Sample - Superstore'!$R2:$R1000/monthly_target))"),"") | K3: =IF(I2>=1,"OK","ALERTA") -> OK
I5: INSIGHT C F I
I6: Contexto
I7: Mes Seleccionado | K7: =M2 -> 2016-11
B8: Selected Month | C8: South | D8: West | E8: Central | F8: East | I8: Hallazgo
B9: =IFERROR(__xludf.DUMMYFUNCTION("FILTER(summary!A:F, TEXT(summary!A:A,""yyyymm"") = TEXT(Selected_Month,""yyyymm""))"),"2016-11") -> 2016-11 | C9: =IFERROR(__xludf.DUMMYFUNCTION("""COMPUTED_VALUE"""),11441.487922959708) -> 11441.488 | D9: =IFERROR(__xludf.DUMMYFUNCTION("""COMPUTED_VALUE"""),23923.00499999999) -> 23923.005 | E9: =IFERROR(__xludf.DUMMYFUNCTION("""COMPUTED_VALUE"""),19140.531822716046) -> 19140.532 | F9: =IFERROR(__xludf.DUMMYFUNCTION("""COMPUTED_VALUE"""),26019.6307707819) -> 26019.631 | I9: Por Determinar
I11: Implicación
I12: Por Determinar

Sheet Dashboard_product
A1: SALES USD | E1: Profit | I1: Avance | M1: Mes | N1: Producto | P1: Sales (USD) | T1: Profit (USD) | X1: Units (Quantity)
A2: =SUMIFS('Sample - Superstore'!$R:$R,'Sample - Superstore'!$V:$V,Dashboard_product!Selected_Month) -> 51788.555 | E2: =SUMIFS('Sample - Superstore'!$U:$U,'Sample - Superstore'!$V:$V,Dashboard_product!Selected_Month) -> 3554.9957 | I2: =IFERROR(SUMIFS('Sample - Superstore'!$R:$R,'Sample - Superstore'!$V:$V,Dashboard_product!Selected_Month)/monthly_target,0) -> 51.788555 | M2: 2016-03 | N2: Recycled Steel Personal File for Hanging File Folders | P2: =SUMIFS('Sample - Superstore'!$R:$R, 'Sample - Superstore'!$V:$V, Dashboard_product!Selected_Month, 'Sample - Superstore'!$Q:$Q, Producto) -> 0 | T2: =SUMIFS('Sample - Superstore'!$U:$U, 'Sample - Superstore'!$V:$V, Dashboard_product!Selected_Month, 'Sample - Superstore'!$Q:$Q, Producto) -> 0 | X2: =SUMIFS('Sample - Superstore'!$S:$S, 'Sample - Superstore'!$V:$V, Dashboard_product!Selected_Month, 'Sample - Superstore'!$Q:$Q, Producto) -> 0
A3: =IFERROR(__xludf.DUMMYFUNCTION("SPARKLINE(FILTER('Sample - Superstore'!R:R,TEXT('Sample - Superstore'!V:V,""yyyymm"")=TEXT(Dashboard_product!Selected_Month,""yyyymm""))) "),"") | C3: =IF(A2>=1,"OK","ALERTA") -> OK | E3: =IFERROR(__xludf.DUMMYFUNCTION("SPARKLINE(FILTER('Sample - Superstore'!$U:$U,'Sample - Superstore'!$V:$V<=Dashboard_product!Selected_Month))"),"") | G3: =IF(E2>=1,"OK","ALERTA") -> OK | I3: =IFERROR(__xludf.DUMMYFUNCTION("SPARKLINE(ARRAYFORMULA('Sample - Superstore'!$R2:$R1000/monthly_target))"),"") | K3: =IF(I2>=1,"OK","ALERTA") -> OK | P3: =IFERROR(__xludf.DUMMYFUNCTION("SPARKLINE(ARRAYFORMULA('Sample - Superstore'!$R2:$R1000/monthly_target))"),"") | R3: =IF(P2>=1,"OK","ALERTA") -> ALERTA | T3: =IFERROR(__xludf.DUMMYFUNCTION("SPARKLINE(ARRAYFORMULA('Sample - Superstore'!$R2:$R1000/monthly_target))"),"") | V3: =IF(T2>=1,"OK","ALERTA") -> ALERTA | X3: =IFERROR(__xludf.DUMMYFUNCTION("SPARKLINE(ARRAYFORMULA('Sample - Superstore'!$R2:$R1000/monthly_target))"),"") | Z3: =IF(X2>=1,"OK","ALERTA") -> ALERTA
I5: INSIGHT C F I | M5: Descuento
I6: Contexto | M6: =AVERAGEIFS('Sample - Superstore'!T:T,'Sample - Superstore'!V:V,Dashboard_product!Selected_Month,'Sample - Superstore'!Q:Q,Producto) -> #DIV/0!
I7: Mes Seleccionado | K7: =M2 -> 2016-03
B8: Selected Month | C8: South | D8: West | E8: Central | F8: East | I8: Hallazgo
B9: =IFERROR(__xludf.DUMMYFUNCTION("FILTER(summary!A:F, TEXT(summary!A:A,""yyyymm"") = TEXT(Dashboard_product!Selected_Month,""yyyymm""))"),"2016-03") -> 2016-03 | C9: =IFERROR(__xludf.DUMMYFUNCTION("""COMPUTED_VALUE"""),3449.6369068081653) -> 3449.6369 | D9: =IFERROR(__xludf.DUMMYFUNCTION("""COMPUTED_VALUE"""),17559.031) -> 17559.031 | E9: =IFERROR(__xludf.DUMMYFUNCTION("""COMPUTED_VALUE"""),13538.035930864193) -> 13538.036 | F9: =IFERROR(__xludf.DUMMYFUNCTION("""COMPUTED_VALUE"""),17241.850822633747) -> 17241.851 | I9: Por Determinar
I11: Implicación
I12: Por Determinar

Sheet product_summary
A1: Month | B1: Product ID | C1: Category | D1: Sub-Category | E1: Product Name | F1: Sales | G1: Flag_Outlier | H1: Quantity | I1: Discount | J1: Profit | K1: Producto | L1: Product ID | M1: Mes | N1: Month | O1: AVG Discount
A2: 2016-01 | B2: FUR-BO-10004709 | C2: Furniture | D2: Bookcases | E2: Bush Westfield Collection Bookcases, Medium Cherry Finish | F2: =SUMIFS('Sample - Superstore'!R:R,'Sample - Superstore'!$V:$V,$A2,'Sample - Superstore'!$N:$N,$B2) -> 174.01158 | G2: =IF(OR($F2<Lower_Limit,$F2>Upper_Limit),TRUE,IF($F2>Upper_percentile,"P99",IF($F2<Lower_percentile,"P01",""))) | H2: =SUMIFS('Sample - Superstore'!S:S,'Sample - Superstore'!$V:$V,$A2,'Sample - Superstore'!$N:$N,$B2) -> 3 | I2: =SUMIFS('Sample - Superstore'!T:T,'Sample - Superstore'!$V:$V,$A2,'Sample - Superstore'!$N:$N,$B2) -> 0 | J2: =SUMIFS('Sample - Superstore'!U:U,'Sample - Superstore'!$V:$V,$A2,'Sample - Superstore'!$N:$N,$B2) -> 38.282548 | L2: FUR-BO-10004709 | M2: 42430 | N2: 42370 | O2: =AVERAGEIFS('Sample - Superstore'!T:T,'Sample - Superstore'!V:V,Selected_Month,'Sample - Superstore'!Q:Q,#REF!) -> #DIV/0!
A3: 2016-01 | B3: TEC-PH-10000455 | C3: Technology | D3: Phones | E3: GE 30522EE2 | F3: =SUMIFS('Sample - Superstore'!R:R,'Sample - Superstore'!$V:$V,$A3,'Sample - Superstore'!$N:$N,$B3) -> 232.07547 | G3: =IF(OR($F3<Lower_Limit,$F3>Upper_Limit),TRUE,IF($F3>Upper_percentile,"P99",IF($F3<Lower_percentile,"P01",""))) | H3: =SUMIFS('Sample - Superstore'!S:S,'Sample - Superstore'!$V:$V,$A3,'Sample - Superstore'!$N:$N,$B3) -> 2 | I3: =SUMIFS('Sample - Superstore'!T:T,'Sample - Superstore'!$V:$V,$A3,'Sample - Superstore'!$N:$N,$B3) -> 0 | J3: =SUMIFS('Sample - Superstore'!U:U,'Sample - Superstore'!$V:$V,$A3,'Sample - Superstore'!$N:$N,$B3) -> 67.301885 | L3: TEC-PH-10000455 | N3: 42401
A4: 2016-01 | B4: OFF-ST-10003692 | C4: Office Supplies | D4: Storage | E4: Recycled Steel Personal File for Hanging File Folders | F4: =SUMIFS('Sample - Superstore'!R:R,'Sample - Superstore'!$V:$V,$A4,'Sample - Superstore'!$N:$N,$B4) -> 114.46 | G4: =IF(OR($F4<Lower_Limit,$F4>Upper_Limit),TRUE,IF($F4>Upper_percentile,"P99",IF($F4<Lower_percentile,"P01",""))) | H4: =SUMIFS('Sample - Superstore'!S:S,'Sample - Superstore'!$V:$V,$A4,'Sample - Superstore'!$N:$N,$B4) -> 2 | I4: =SUMIFS('Sample - Superstore'!T:T,'Sample - Superstore'!$V:$V,$A4,'Sample - Superstore'!$N:$N,$B4) -> 0 | J4: =SUMIFS('Sample - Superstore'!U:U,'Sample - Superstore'!$V:$V,$A4,'Sample - Superstore'!$N:$N,$B4) -> 28.615 | L4: OFF-ST-10003692 | N4: 42430
A5: 2016-01 | B5: TEC-AC-10002217 | C5: Technology | D5: Accessories | E5: ImationÂ Clip USBÂ flash driveÂ - 8 GB | F5: =SUMIFS('Sample - Superstore'!R:R,'Sample - Superstore'!$V:$V,$A5,'Sample - Superstore'!$N:$N,$B5) -> 30.104757 | G5: =IF(OR($F5<Lower_Limit,$F5>Upper_Limit),TRUE,IF($F5>Upper_percentile,"P99",IF($F5<Lower_percentile,"P01",""))) | H5: =SUMIFS('Sample - Superstore'!S:S,'Sample - Superstore'!$V:$V,$A5,'Sample - Superstore'!$N:$N,$B5) -> 2 | I5: =SUMIFS('Sample - Superstore'!T:T,'Sample - Superstore'!$V:$V,$A5,'Sample - Superstore'!$N:$N,$B5) -> 0.2 | J5: =SUMIFS('Sample - Superstore'!U:U,'Sample - Superstore'!$V:$V,$A5,'Sample - Superstore'!$N:$N,$B5) -> -5.2683325 | L5: TEC-AC-10002217 | N5: 42461
A6: 2016-01 | B6: TEC-AC-10002942 | C6: Technology | D6: Accessories | E6: WD My Passport Ultra 1TB Portable External Hard Drive | F6: =SUMIFS('Sample - Superstore'!R:R,'Sample - Superstore'!$V:$V,$A6,'Sample - Superstore'!$N:$N,$B6) -> 165.7363 | G6: =IF(OR($F6<Lower_Limit,$F6>Upper_Limit),TRUE,IF($F6>Upper_percentile,"P99",IF($F6<Lower_percentile,"P01",""))) | H6: =SUMIFS('Sample - Superstore'!S:S,'Sample - Superstore'!$V:$V,$A6,'Sample - Superstore'!$N:$N,$B6) -> 3 | I6: =SUMIFS('Sample - Superstore'!T:T,'Sample - Superstore'!$V:$V,$A6,'Sample - Superstore'!$N:$N,$B6) -> 0.2 | J6: =SUMIFS('Sample - Superstore'!U:U,'Sample - Superstore'!$V:$V,$A6,'Sample - Superstore'!$N:$N,$B6) -> -6.2151111 | L6: TEC-AC-10002942 | N6: 42491
A7: 2016-01 | B7: TEC-PH-10002890 | C7: Technology | D7: Phones | E7: AT&T 17929 Lendline Telephone | F7: =SUMIFS('Sample - Superstore'!R:R,'Sample - Superstore'!$V:$V,$A7,'Sample - Superstore'!$N:$N,$B7) -> 181.10894 | G7: =IF(OR($F7<Lower_Limit,$F7>Upper_Limit),TRUE,IF($F7>Upper_percentile,"P99",IF($F7<Lower_percentile,"P01",""))) | H7: =SUMIFS('Sample - Superstore'!S:S,'Sample - Superstore'!$V:$V,$A7,'Sample - Superstore'!$N:$N,$B7) -> 5 | I7: =SUMIFS('Sample - Superstore'!T:T,'Sample - Superstore'!$V:$V,$A7,'Sample - Superstore'!$N:$N,$B7) -> 0.2 | J7: =SUMIFS('Sample - Superstore'!U:U,'Sample - Superstore'!$V:$V,$A7,'Sample - Superstore'!$N:$N,$B7) -> 13.58317 | L7: TEC-PH-10002890 | N7: 42522
A8: 2016-01 | B8: FUR-TA-10000617 | C8: Furniture | D8: Tables | E8: Hon Practical Foundations 30 x 60 Training Table, Light Gray/Charcoal | F8: =SUMIFS('Sample - Superstore'!R:R,'Sample - Superstore'!$V:$V,$A8,'Sample - Superstore'!$N:$N,$B8) -> 1594.161 | G8: =IF(OR($F8<Lower_Limit,$F8>Upper_Limit),TRUE,IF($F8>Upper_percentile,"P99",IF($F8<Lower_percentile,"P01",""))) | H8: =SUMIFS('Sample - Superstore'!S:S,'Sample - Superstore'!$V:$V,$A8,'Sample - Superstore'!$N:$N,$B8) -> 7 | I8: =SUMIFS('Sample - Superstore'!T:T,'Sample - Superstore'!$V:$V,$A8,'Sample - Superstore'!$N:$N,$B8) -> 0 | J8: =SUMIFS('Sample - Superstore'!U:U,'Sample - Superstore'!$V:$V,$A8,'Sample - Superstore'!$N:$N,$B8) -> 350.71542 | L8: FUR-TA-10000617 | N8: 42552
A9: 2016-01 | B9: OFF-BI-10004364 | C9: Office Supplies | D9: Binders | E9: Storex Dura Pro Binders | F9: =SUMIFS('Sample - Superstore'!R:R,'Sample - Superstore'!$V:$V,$A9,'Sample - Superstore'!$N:$N,$B9) -> 11.889778 | G9: =IF(OR($F9<Lower_Limit,$F9>Upper_Limit),TRUE,IF($F9>Upper_percentile,"P99",IF($F9<Lower_percentile,"P01",""))) | H9: =SUMIFS('Sample - Superstore'!S:S,'Sample - Superstore'!$V:$V,$A9,'Sample - Superstore'!$N:$N,$B9) -> 2 | I9: =SUMIFS('Sample - Superstore'!T:T,'Sample - Superstore'!$V:$V,$A9,'Sample - Superstore'!$N:$N,$B9) -> 0 | J9: =SUMIFS('Sample - Superstore'!U:U,'Sample - Superstore'!$V:$V,$A9,'Sample - Superstore'!$N:$N,$B9) -> 5.3504 | L9: OFF-BI-10004364 | N9: 42583
A10: 2016-01 | B10: TEC-CO-10000971 | C10: Technology | D10: Copiers | E10: Hewlett Packard 310 Color Digital Copier | F10: =SUMIFS('Sample - Superstore'!R:R,'Sample - Superstore'!$V:$V,$A10,'Sample - Superstore'!$N:$N,$B10) -> 800.5794 | G10: =IF(OR($F10<Lower_Limit,$F10>Upper_Limit),TRUE,IF($F10>Upper_percentile,"P99",IF($F10<Lower_percentile,"P01",""))) | H10: =SUMIFS('Sample - Superstore'!S:S,'Sample - Superstore'!$V:$V,$A10,'Sample - Superstore'!$N:$N,$B10) -> 4 | I10: =SUMIFS('Sample - Superstore'!T:T,'Sample - Superstore'!$V:$V,$A10,'Sample - Superstore'!$N:$N,$B10) -> 0.2 | J10: =SUMIFS('Sample - Superstore'!U:U,'Sample - Superstore'!$V:$V,$A10,'Sample - Superstore'!$N:$N,$B10) -> 100.07243 | L10: TEC-CO-10000971 | N10: 42614
A11: 2016-01 | B11: OFF-AR-10004078 | C11: Office Supplies | D11: Art | E11: Newell 312 | F11: =SUMIFS('Sample - Superstore'!R:R,'Sample - Superstore'!$V:$V,$A11,'Sample - Superstore'!$N:$N,$B11) -> 4.6777679 | G11: =IF(OR($F11<Lower_Limit,$F11>Upper_Limit),TRUE,IF($F11>Upper_percentile,"P99",IF($F11<Lower_percentile,"P01",""))) | H11: =SUMIFS('Sample - Superstore'!S:S,'Sample - Superstore'!$V:$V,$A11,'Sample - Superstore'!$N:$N,$B11) -> 1 | I11: =SUMIFS('Sample - Superstore'!T:T,'Sample - Superstore'!$V:$V,$A11,'Sample - Superstore'!$N:$N,$B11) -> 0.2 | J11: =SUMIFS('Sample - Superstore'!U:U,'Sample - Superstore'!$V:$V,$A11,'Sample - Superstore'!$N:$N,$B11) -> 0.58472099 | L11: OFF-AR-10004078 | N11: 42644
A12: 2016-01 | B12: OFF-BI-10002026 | C12: Office Supplies | D12: Binders | E12: Avery Arch Ring Binders | F12: =SUMIFS('Sample - Superstore'!R:R,'Sample - Superstore'!$V:$V,$A12,'Sample - Superstore'!$N:$N,$B12) -> 104.70911 | G12: =IF(OR($F12<Lower_Limit,$F12>Upper_Limit),TRUE,IF($F12>Upper_percentile,"P99",IF($F12<Lower_percentile,"P01",""))) | H12: =SUMIFS('Sample - Superstore'!S:S,'Sample - Superstore'!$V:$V,$A12,'Sample - Superstore'!$N:$N,$B12) -> 6 | I12: =SUMIFS('Sample - Superstore'!T:T,'Sample - Superstore'!$V:$V,$A12,'Sample - Superstore'!$N:$N,$B12) -> 0.7 | J12: =SUMIFS('Sample - Superstore'!U:U,'Sample - Superstore'!$V:$V,$A12,'Sample - Superstore'!$N:$N,$B12) -> -80.276985 | L12: OFF-BI-10002026 | N12: 42675
A13: 2016-01 | B13: TEC-AC-10001714 | C13: Technology | D13: Accessories | E13: LogitechÂ MX Performance Wireless Mouse | F13: =SUMIFS('Sample - Superstore'!R:R,'Sample - Superstore'!$V:$V,$A13,'Sample - Superstore'!$N:$N,$B13) -> 161.26514 | G13: =IF(OR($F13<Lower_Limit,$F13>Upper_Limit),TRUE,IF($F13>Upper_percentile,"P99",IF($F13<Lower_percentile,"P01",""))) | H13: =SUMIFS('Sample - Superstore'!S:S,'Sample - Superstore'!$V:$V,$A13,'Sample - Superstore'!$N:$N,$B13) -> 6 | I13: =SUMIFS('Sample - Superstore'!T:T,'Sample - Superstore'!$V:$V,$A13,'Sample - Superstore'!$N:$N,$B13) -> 0.2 | J13: =SUMIFS('Sample - Superstore'!U:U,'Sample - Superstore'!$V:$V,$A13,'Sample - Superstore'!$N:$N,$B13) -> 34.268843 | L13: TEC-AC-10001714 | N13: 42705
A14: 2016-01 | B14: OFF-AR-10003958 | C14: Office Supplies | D14: Art | E14: Newell 337 | F14: =SUMIFS('Sample - Superstore'!R:R,'Sample - Superstore'!$V:$V,$A14,'Sample - Superstore'!$N:$N,$B14) -> 4.4300674 | G14: =IF(OR($F14<Lower_Limit,$F14>Upper_Limit),TRUE,IF($F14>Upper_percentile,"P99",IF($F14<Lower_percentile,"P01",""))) | H14: =SUMIFS('Sample - Superstore'!S:S,'Sample - Superstore'!$V:$V,$A14,'Sample - Superstore'!$N:$N,$B14) -> 2 | I14: =SUMIFS('Sample - Superstore'!T:T,'Sample - Superstore'!$V:$V,$A14,'Sample - Superstore'!$N:$N,$B14) -> 0.2 | J14: =SUMIFS('Sample - Superstore'!U:U,'Sample - Superstore'!$V:$V,$A14,'Sample - Superstore'!$N:$N,$B14) -> 0.49838258 | L14: OFF-AR-10003958 | N14: 42736
... A25: 2016-01 | B25: TEC-PH-10002726 | C25: Technology | D25: Phones | E25: netTALK DUO VoIP Telephone Service | F25: =SUMIFS('Sample - Superstore'!R:R,'Sample - Superstore'!$V:$V,$A25,'Sample - Superstore'!$N:$N,$B25) -> 377.928 | G25: =IF(OR($F25<Lower_Limit,$F25>Upper_Limit),TRUE,IF($F25>Upper_percentile,"P99",IF($F25<Lower_percentile,"P01",""))) | H25: =SUMIFS('Sample - Superstore'!S:S,'Sample - Superstore'!$V:$V,$A25,'Sample - Superstore'!$N:$N,$B25) -> 9 | I25: =SUMIFS('Sample - Superstore'!T:T,'Sample - Superstore'!$V:$V,$A25,'Sample - Superstore'!$N:$N,$B25) -> 0.2 | J25: =SUMIFS('Sample - Superstore'!U:U,'Sample - Superstore'!$V:$V,$A25,'Sample - Superstore'!$N:$N,$B25) -> 141.723 | L25: TEC-PH-10002726 | N25: 43070
A26: 2016-01 | B26: FUR-FU-10002445 | C26: Furniture | D26: Furnishings | E26: DAX Two-Tone Rosewood/Black Document Frame, Desktop, 5 x 7 | F26: =SUMIFS('Sample - Superstore'!R:R,'Sample - Superstore'!$V:$V,$A26,'Sample - Superstore'!$N:$N,$B26) -> 15.217936 | G26: =IF(OR($F26<Lower_Limit,$F26>Upper_Limit),TRUE,IF($F26>Upper_percentile,"P99",IF($F26<Lower_percentile,"P01",""))) | H26: =SUMIFS('Sample - Superstore'!S:S,'Sample - Superstore'!$V:$V,$A26,'Sample - Superstore'!$N:$N,$B26) -> 2 | I26: =SUMIFS('Sample - Superstore'!T:T,'Sample - Superstore'!$V:$V,$A26,'Sample - Superstore'!$N:$N,$B26) -> 0.2 | J26: =SUMIFS('Sample - Superstore'!U:U,'Sample - Superstore'!$V:$V,$A26,'Sample - Superstore'!$N:$N,$B26) -> 3.804484 | L26: FUR-FU-10002445
A27: 2016-01 | B27: FUR-FU-10000076 | C27: Furniture | D27: Furnishings | E27: 24-Hour Round Wall Clock | F27: =SUMIFS('Sample - Superstore'!R:R,'Sample - Superstore'!$V:$V,$A27,'Sample - Superstore'!$N:$N,$B27) -> 79.92 | G27: =IF(OR($F27<Lower_Limit,$F27>Upper_Limit),TRUE,IF($F27>Upper_percentile,"P99",IF($F27<Lower_percentile,"P01",""))) | H27: =SUMIFS('Sample - Superstore'!S:S,'Sample - Superstore'!$V:$V,$A27,'Sample - Superstore'!$N:$N,$B27) -> 4 | I27: =SUMIFS('Sample - Superstore'!T:T,'Sample - Superstore'!$V:$V,$A27,'Sample - Superstore'!$N:$N,$B27) -> 0 | J27: =SUMIFS('Sample - Superstore'!U:U,'Sample - Superstore'!$V:$V,$A27,'Sample - Superstore'!$N:$N,$B27) -> 34.3656 | L27: FUR-FU-10000076
A28: 2016-01 | B28: TEC-AC-10002335 | C28: Technology | D28: Accessories | E28: Logitech Media Keyboard K200 | F28: =SUMIFS('Sample - Superstore'!R:R,'Sample - Superstore'!$V:$V,$A28,'Sample - Superstore'!$N:$N,$B28) -> 69.98 | G28: =IF(OR($F28<Lower_Limit,$F28>Upper_Limit),TRUE,IF($F28>Upper_percentile,"P99",IF($F28<Lower_percentile,"P01",""))) | H28: =SUMIFS('Sample - Superstore'!S:S,'Sample - Superstore'!$V:$V,$A28,'Sample - Superstore'!$N:$N,$B28) -> 2 | I28: =SUMIFS('Sample - Superstore'!T:T,'Sample - Superstore'!$V:$V,$A28,'Sample - Superstore'!$N:$N,$B28) -> 0 | J28: =SUMIFS('Sample - Superstore'!U:U,'Sample - Superstore'!$V:$V,$A28,'Sample - Superstore'!$N:$N,$B28) -> 13.2962 | L28: TEC-AC-10002335
A29: 2016-01 | B29: FUR-FU-10000010 | C29: Furniture | D29: Furnishings | E29: DAX Value U-Channel Document Frames, Easel Back | F29: =SUMIFS('Sample - Superstore'!R:R,'Sample - Superstore'!$V:$V,$A29,'Sample - Superstore'!$N:$N,$B29) -> 24.85 | G29: =IF(OR($F29<Lower_Limit,$F29>Upper_Limit),TRUE,IF($F29>Upper_percentile,"P99",IF($F29<Lower_percentile,"P01",""))) | H29: =SUMIFS('Sample - Superstore'!S:S,'Sample - Superstore'!$V:$V,$A29,'Sample - Superstore'!$N:$N,$B29) -> 5 | I29: =SUMIFS('Sample - Superstore'!T:T,'Sample - Superstore'!$V:$V,$A29,'Sample - Superstore'!$N:$N,$B29) -> 0 | J29: =SUMIFS('Sample - Superstore'!U:U,'Sample - Superstore'!$V:$V,$A29,'Sample - Superstore'!$N:$N,$B29) -> 7.7035 | L29: FUR-FU-10000010
A30: 2016-01 | B30: OFF-PA-10001166 | C30: Office Supplies | D30: Paper | E30: Xerox 2 | F30: =SUMIFS('Sample - Superstore'!R:R,'Sample - Superstore'!$V:$V,$A30,'Sample - Superstore'!$N:$N,$B30) -> 15.616 | G30: =IF(OR($F30<Lower_Limit,$F30>Upper_Limit),TRUE,IF($F30>Upper_percentile,"P99",IF($F30<Lower_percentile,"P01",""))) | H30: =SUMIFS('Sample - Superstore'!S:S,'Sample - Superstore'!$V:$V,$A30,'Sample - Superstore'!$N:$N,$B30) -> 3 | I30: =SUMIFS('Sample - Superstore'!T:T,'Sample - Superstore'!$V:$V,$A30,'Sample - Superstore'!$N:$N,$B30) -> 0.2 | J30: =SUMIFS('Sample - Superstore'!U:U,'Sample - Superstore'!$V:$V,$A30,'Sample - Superstore'!$N:$N,$B30) -> 5.4656 | L30: OFF-PA-10001166
A31: 2016-01 | B31: OFF-PA-10003656 | C31: Office Supplies | D31: Paper | E31: Xerox 1935 | F31: =SUMIFS('Sample - Superstore'!R:R,'Sample - Superstore'!$V:$V,$A31,'Sample - Superstore'!$N:$N,$B31) -> 63.572543 | G31: =IF(OR($F31<Lower_Limit,$F31>Upper_Limit),TRUE,IF($F31>Upper_percentile,"P99",IF($F31<Lower_percentile,"P01",""))) | H31: =SUMIFS('Sample - Superstore'!S:S,'Sample - Superstore'!$V:$V,$A31,'Sample - Superstore'!$N:$N,$B31) -> 3 | I31: =SUMIFS('Sample - Superstore'!T:T,'Sample - Superstore'!$V:$V,$A31,'Sample - Superstore'!$N:$N,$B31) -> 0.2 | J31: =SUMIFS('Sample - Superstore'!U:U,'Sample - Superstore'!$V:$V,$A31,'Sample - Superstore'!$N:$N,$B31) -> 20.661077 | L31: OFF-PA-10003656
A32: 2016-01 | B32: TEC-PH-10000148 | C32: Technology | D32: Phones | E32: Cyber Acoustics AC-202b Speech Recognition Stereo Headset | F32: =SUMIFS('Sample - Superstore'!R:R,'Sample - Superstore'!$V:$V,$A32,'Sample - Superstore'!$N:$N,$B32) -> 15.652148 | G32: =IF(OR($F32<Lower_Limit,$F32>Upper_Limit),TRUE,IF($F32>Upper_percentile,"P99",IF($F32<Lower_percentile,"P01",""))) | H32: =SUMIFS('Sample - Superstore'!S:S,'Sample - Superstore'!$V:$V,$A32,'Sample - Superstore'!$N:$N,$B32) -> 2 | I32: =SUMIFS('Sample - Superstore'!T:T,'Sample - Superstore'!$V:$V,$A32,'Sample - Superstore'!$N:$N,$B32) -> 0.4 | J32: =SUMIFS('Sample - Superstore'!U:U,'Sample - Superstore'!$V:$V,$A32,'Sample - Superstore'!$N:$N,$B32) -> -9.9130272 | L32: TEC-PH-10000148
A33: 2016-01 | B33: FUR-FU-10002268 | C33: Furniture | D33: Furnishings | E33: Ultra Door Push Plate | F33: =SUMIFS('Sample - Superstore'!R:R,'Sample - Superstore'!$V:$V,$A33,'Sample - Superstore'!$N:$N,$B33) -> 55.218305 | G33: =IF(OR($F33<Lower_Limit,$F33>Upper_Limit),TRUE,IF($F33>Upper_percentile,"P99",IF($F33<Lower_percentile,"P01",""))) | H33: =SUMIFS('Sample - Superstore'!S:S,'Sample - Superstore'!$V:$V,$A33,'Sample - Superstore'!$N:$N,$B33) -> 14 | I33: =SUMIFS('Sample - Superstore'!T:T,'Sample - Superstore'!$V:$V,$A33,'Sample - Superstore'!$N:$N,$B33) -> 0.2 | J33: =SUMIFS('Sample - Superstore'!U:U,'Sample - Superstore'!$V:$V,$A33,'Sample - Superstore'!$N:$N,$B33) -> 8.9729745 | L33: FUR-FU-10002268
A34: 2016-01 | B34: OFF-PA-10004039 | C34: Office Supplies | D34: Paper | E34: Xerox 1882 | F34: =SUMIFS('Sample - Superstore'!R:R,'Sample - Superstore'!$V:$V,$A34,'Sample - Superstore'!$N:$N,$B34) -> 75.156385 | G34: =IF(OR($F34<Lower_Limit,$F34>Upper_Limit),TRUE,IF($F34>Upper_percentile,"P99",IF($F34<Lower_percentile,"P01",""))) | H34: =SUMIFS('Sample - Superstore'!S:S,'Sample - Superstore'!$V:$V,$A34,'Sample - Superstore'!$N:$N,$B34) -> 2 | I34: =SUMIFS('Sample - Superstore'!T:T,'Sample - Superstore'!$V:$V,$A34,'Sample - Superstore'!$N:$N,$B34) -> 0.2 | J34: =SUMIFS('Sample - Superstore'!U:U,'Sample - Superstore'!$V:$V,$A34,'Sample - Superstore'!$N:$N,$B34) -> 27.244189 | L34: OFF-PA-10004039
A35: 2016-01 | B35: FUR-FU-10003374 | C35: Furniture | D35: Furnishings | E35: Electrix Fluorescent Magnifier Lamps & Weighted Base | F35: =SUMIFS('Sample - Superstore'!R:R,'Sample - Superstore'!$V:$V,$A35,'Sample - Superstore'!$N:$N,$B35) -> 265.9459 | G35: =IF(OR($F35<Lower_Limit,$F35>Upper_Limit),TRUE,IF($F35>Upper_percentile,"P99",IF($F35<Lower_percentile,"P01",""))) | H35: =SUMIFS('Sample - Superstore'!S:S,'Sample - Superstore'!$V:$V,$A35,'Sample - Superstore'!$N:$N,$B35) -> 8 | I35: =SUMIFS('Sample - Superstore'!T:T,'Sample - Superstore'!$V:$V,$A35,'Sample - Superstore'!$N:$N,$B35) -> 0.2 | J35: =SUMIFS('Sample - Superstore'!U:U,'Sample - Superstore'!$V:$V,$A35,'Sample - Superstore'!$N:$N,$B35) -> 26.59459 | L35: FUR-FU-10003374
A36: 2016-01 | B36: OFF-EN-10003040 | C36: Office Supplies | D36: Envelopes | E36: Quality Park Security Envelopes | F36: =SUMIFS('Sample - Superstore'!R:R,'Sample - Superstore'!$V:$V,$A36,'Sample - Superstore'!$N:$N,$B36) -> 52.641547 | G36: =IF(OR($F36<Lower_Limit,$F36>Upper_Limit),TRUE,IF($F36>Upper_percentile,"P99",IF($F36<Lower_percentile,"P01",""))) | H36: =SUMIFS('Sample - Superstore'!S:S,'Sample - Superstore'!$V:$V,$A36,'Sample - Superstore'!$N:$N,$B36) -> 2 | I36: =SUMIFS('Sample - Superstore'!T:T,'Sample - Superstore'!$V:$V,$A36,'Sample - Superstore'!$N:$N,$B36) -> 0 | J36: =SUMIFS('Sample - Superstore'!U:U,'Sample - Superstore'!$V:$V,$A36,'Sample - Superstore'!$N:$N,$B36) -> 24.741527 | L36: OFF-EN-10003040
A37: 2016-01 | B37: OFF-AR-10001573 | C37: Office Supplies | D37: Art | E37: American Pencil | F37: =SUMIFS('Sample - Superstore'!R:R,'Sample - Superstore'!$V:$V,$A37,'Sample - Superstore'!$N:$N,$B37) -> 4.6868477 | G37: =IF(OR($F37<Lower_Limit,$F37>Upper_Limit),TRUE,IF($F37>Upper_percentile,"P99",IF($F37<Lower_percentile,"P01",""))) | H37: =SUMIFS('Sample - Superstore'!S:S,'Sample - Superstore'!$V:$V,$A37,'Sample - Superstore'!$N:$N,$B37) -> 2 | I37: =SUMIFS('Sample - Superstore'!T:T,'Sample - Superstore'!$V:$V,$A37,'Sample - Superstore'!$N:$N,$B37) -> 0 | J37: =SUMIFS('Sample - Superstore'!U:U,'Sample - Superstore'!$V:$V,$A37,'Sample - Superstore'!$N:$N,$B37) -> 1.3591858 | L37: OFF-AR-10001573
... A1756: 2016-10 | B1756: OFF-FA-10003059 | C1756: Office Supplies | D1756: Fasteners | E1756: Assorted Color Push Pins | F1756: =SUMIFS('Sample - Superstore'!R:R,'Sample - Superstore'!$V:$V,$A1756,'Sample - Superstore'!$N:$N,$B1756) -> 3.62 | G1756: =IF(OR($F1756<Lower_Limit,$F1756>Upper_Limit),TRUE,IF($F1756>Upper_percentile,"P99",IF($F1756<Lower_percentile,"P01",""))) | H1756: =SUMIFS('Sample - Superstore'!S:S,'Sample - Superstore'!$V:$V,$A1756,'Sample - Superstore'!$N:$N,$B1756) -> 2 | I1756: =SUMIFS('Sample - Superstore'!T:T,'Sample - Superstore'!$V:$V,$A1756,'Sample - Superstore'!$N:$N,$B1756) -> 0 | J1756: =SUMIFS('Sample - Superstore'!U:U,'Sample - Superstore'!$V:$V,$A1756,'Sample - Superstore'!$N:$N,$B1756) -> 1.1946 | L1756: OFF-FA-10000089
A1757: 2016-10 | B1757: FUR-CH-10000988 | C1757: Furniture | D1757: Chairs | E1757: Hon Olson Stacker Stools | F1757: =SUMIFS('Sample - Superstore'!R:R,'Sample - Superstore'!$V:$V,$A1757,'Sample - Superstore'!$N:$N,$B1757) -> 554.49008 | G1757: =IF(OR($F1757<Lower_Limit,$F1757>Upper_Limit),TRUE,IF($F1757>Upper_percentile,"P99",IF($F1757<Lower_percentile,"P01",""))) | H1757: =SUMIFS('Sample - Superstore'!S:S,'Sample - Superstore'!$V:$V,$A1757,'Sample - Superstore'!$N:$N,$B1757) -> 5 | I1757: =SUMIFS('Sample - Superstore'!T:T,'Sample - Superstore'!$V:$V,$A1757,'Sample - Superstore'!$N:$N,$B1757) -> 0.3 | J1757: =SUMIFS('Sample - Superstore'!U:U,'Sample - Superstore'!$V:$V,$A1757,'Sample - Superstore'!$N:$N,$B1757) -> -15.842574
A1758: 2016-10 | B1758: OFF-ST-10002615 | C1758: Office Supplies | D1758: Storage | E1758: Dual Level, Single-Width Filing Carts | F1758: =SUMIFS('Sample - Superstore'!R:R,'Sample - Superstore'!$V:$V,$A1758,'Sample - Superstore'!$N:$N,$B1758) -> 1085.42 | G1758: =IF(OR($F1758<Lower_Limit,$F1758>Upper_Limit),TRUE,IF($F1758>Upper_percentile,"P99",IF($F1758<Lower_percentile,"P01",""))) | H1758: =SUMIFS('Sample - Superstore'!S:S,'Sample - Superstore'!$V:$V,$A1758,'Sample - Superstore'!$N:$N,$B1758) -> 7 | I1758: =SUMIFS('Sample - Superstore'!T:T,'Sample - Superstore'!$V:$V,$A1758,'Sample - Superstore'!$N:$N,$B1758) -> 0 | J1758: =SUMIFS('Sample - Superstore'!U:U,'Sample - Superstore'!$V:$V,$A1758,'Sample - Superstore'!$N:$N,$B1758) -> 282.2092
A1759: 2016-10 | B1759: OFF-PA-10002986 | C1759: Office Supplies | D1759: Paper | E1759: Xerox 1898 | F1759: =SUMIFS('Sample - Superstore'!R:R,'Sample - Superstore'!$V:$V,$A1759,'Sample - Superstore'!$N:$N,$B1759) -> 23.702793 | G1759: =IF(OR($F1759<Lower_Limit,$F1759>Upper_Limit),TRUE,IF($F1759>Upper_percentile,"P99",IF($F1759<Lower_percentile,"P01",""))) | H1759: =SUMIFS('Sample - Superstore'!S:S,'Sample - Superstore'!$V:$V,$A1759,'Sample - Superstore'!$N:$N,$B1759) -> 6 | I1759: =SUMIFS('Sample - Superstore'!T:T,'Sample - Superstore'!$V:$V,$A1759,'Sample - Superstore'!$N:$N,$B1759) -> 0.2 | J1759: =SUMIFS('Sample - Superstore'!U:U,'Sample - Superstore'!$V:$V,$A1759,'Sample - Superstore'!$N:$N,$B1759) -> 8.2959775
A1760: 2016-10 | B1760: FUR-CH-10002084 | C1760: Furniture | D1760: Chairs | E1760: Hon Mobius Operator's Chair | F1760: =SUMIFS('Sample - Superstore'!R:R,'Sample - Superstore'!$V:$V,$A1760,'Sample - Superstore'!$N:$N,$B1760) -> 415.12921 | G1760: =IF(OR($F1760<Lower_Limit,$F1760>Upper_Limit),TRUE,IF($F1760>Upper_percentile,"P99",IF($F1760<Lower_percentile,"P01",""))) | H1760: =SUMIFS('Sample - Superstore'!S:S,'Sample - Superstore'!$V:$V,$A1760,'Sample - Superstore'!$N:$N,$B1760) -> 3 | I1760: =SUMIFS('Sample - Superstore'!T:T,'Sample - Superstore'!$V:$V,$A1760,'Sample - Superstore'!$N:$N,$B1760) -> 0 | J1760: =SUMIFS('Sample - Superstore'!U:U,'Sample - Superstore'!$V:$V,$A1760,'Sample - Superstore'!$N:$N,$B1760) -> 91.328426
A1761: 2016-10 | B1761: OFF-AR-10004269 | C1761: Office Supplies | D1761: Art | E1761: Newell 31 | F1761: =SUMIFS('Sample - Superstore'!R:R,'Sample - Superstore'!$V:$V,$A1761,'Sample - Superstore'!$N:$N,$B1761) -> 13.940025 | G1761: =IF(OR($F1761<Lower_Limit,$F1761>Upper_Limit),TRUE,IF($F1761>Upper_percentile,"P99",IF($F1761<Lower_percentile,"P01",""))) | H1761: =SUMIFS('Sample - Superstore'!S:S,'Sample - Superstore'!$V:$V,$A1761,'Sample - Superstore'!$N:$N,$B1761) -> 3 | I1761: =SUMIFS('Sample - Superstore'!T:T,'Sample - Superstore'!$V:$V,$A1761,'Sample - Superstore'!$N:$N,$B1761) -> 0 | J1761: =SUMIFS('Sample - Superstore'!U:U,'Sample - Superstore'!$V:$V,$A1761,'Sample - Superstore'!$N:$N,$B1761) -> 3.9032069
A1762: 2016-10 | B1762: OFF-ST-10001128 | C1762: Office Supplies | D1762: Storage | E1762: Carina Mini System Audio Rack, Model AR050B | F1762: =SUMIFS('Sample - Superstore'!R:R,'Sample - Superstore'!$V:$V,$A1762,'Sample - Superstore'!$N:$N,$B1762) -> 374.59175 | G1762: =IF(OR($F1762<Lower_Limit,$F1762>Upper_Limit),TRUE,IF($F1762>Upper_percentile,"P99",IF($F1762<Lower_percentile,"P01",""))) | H1762: =SUMIFS('Sample - Superstore'!S:S,'Sample - Superstore'!$V:$V,$A1762,'Sample - Superstore'!$N:$N,$B1762) -> 3 | I1762: =SUMIFS('Sample - Superstore'!T:T,'Sample - Superstore'!$V:$V,$A1762,'Sample - Superstore'!$N:$N,$B1762) -> 0 | J1762: =SUMIFS('Sample - Superstore'!U:U,'Sample - Superstore'!$V:$V,$A1762,'Sample - Superstore'!$N:$N,$B1762) -> 11.237753
A1763: 2016-10 | B1763: FUR-CH-10001854 | C1763: Furniture | D1763: Chairs | E1763: Office Star - Professional Matrix Back Chair with 2-to-1 Synchro Tilt and Mesh Fabric Seat | F1763: =SUMIFS('Sample - Superstore'!R:R,'Sample - Superstore'!$V:$V,$A1763,'Sample - Superstore'!$N:$N,$B1763) -> 1403.92 | G1763: =IF(OR($F1763<Lower_Limit,$F1763>Upper_Limit),TRUE,IF($F1763>Upper_percentile,"P99",IF($F1763<Lower_percentile,"P01",""))) | H1763: =SUMIFS('Sample - Superstore'!S:S,'Sample - Superstore'!$V:$V,$A1763,'Sample - Superstore'!$N:$N,$B1763) -> 5 | I1763: =SUMIFS('Sample - Superstore'!T:T,'Sample - Superstore'!$V:$V,$A1763,'Sample - Superstore'!$N:$N,$B1763) -> 0.2 | J1763: =SUMIFS('Sample - Superstore'!U:U,'Sample - Superstore'!$V:$V,$A1763,'Sample - Superstore'!$N:$N,$B1763) -> 70.196
A1764: 2016-11 | B1764: TEC-PH-10003988 | C1764: Technology | D1764: Phones | E1764: LF Elite 3D Dazzle Designer Hard Case Cover, Lf Stylus Pen and Wiper For Apple Iphone 5c Mini Lite | F1764: =SUMIFS('Sample - Superstore'!R:R,'Sample - Superstore'!$V:$V,$A1764,'Sample - Superstore'!$N:$N,$B1764) -> 16.162884 | G1764: =IF(OR($F1764<Lower_Limit,$F1764>Upper_Limit),TRUE,IF($F1764>Upper_percentile,"P99",IF($F1764<Lower_percentile,"P01",""))) | H1764: =SUMIFS('Sample - Superstore'!S:S,'Sample - Superstore'!$V:$V,$A1764,'Sample - Superstore'!$N:$N,$B1764) -> 2 | I1764: =SUMIFS('Sample - Superstore'!T:T,'Sample - Superstore'!$V:$V,$A1764,'Sample - Superstore'!$N:$N,$B1764) -> 0 | J1764: =SUMIFS('Sample - Superstore'!U:U,'Sample - Superstore'!$V:$V,$A1764,'Sample - Superstore'!$N:$N,$B1764) -> 4.5256075
A1765: 2016-11 | B1765: OFF-EN-10002230 | C1765: Office Supplies | D1765: Envelopes | E1765: Airmail Envelopes | F1765: =SUMIFS('Sample - Superstore'!R:R,'Sample - Superstore'!$V:$V,$A1765,'Sample - Superstore'!$N:$N,$B1765) -> 184.80382 | G1765: =IF(OR($F1765<Lower_Limit,$F1765>Upper_Limit),TRUE,IF($F1765>Upper_percentile,"P99",IF($F1765<Lower_percentile,"P01",""))) | H1765: =SUMIFS('Sample - Superstore'!S:S,'Sample - Superstore'!$V:$V,$A1765,'Sample - Superstore'!$N:$N,$B1765) -> 3 | I1765: =SUMIFS('Sample - Superstore'!T:T,'Sample - Superstore'!$V:$V,$A1765,'Sample - Superstore'!$N:$N,$B1765) -> 0 | J1765: =SUMIFS('Sample - Superstore'!U:U,'Sample - Superstore'!$V:$V,$A1765,'Sample - Superstore'!$N:$N,$B1765) -> 86.857795
A1766: 2016-11 | B1766: OFF-ST-10004950 | C1766: Office Supplies | D1766: Storage | E1766: Tenex Personal Filing Tote With Secure Closure Lid, Black/Frost | F1766: =SUMIFS('Sample - Superstore'!R:R,'Sample - Superstore'!$V:$V,$A1766,'Sample - Superstore'!$N:$N,$B1766) -> 125.68844 | G1766: =IF(OR($F1766<Lower_Limit,$F1766>Upper_Limit),TRUE,IF($F1766>Upper_percentile,"P99",IF($F1766<Lower_percentile,"P01",""))) | H1766: =SUMIFS('Sample - Superstore'!S:S,'Sample - Superstore'!$V:$V,$A1766,'Sample - Superstore'!$N:$N,$B1766) -> 9 | I1766: =SUMIFS('Sample - Superstore'!T:T,'Sample - Superstore'!$V:$V,$A1766,'Sample - Superstore'!$N:$N,$B1766) -> 0.2 | J1766: =SUMIFS('Sample - Superstore'!U:U,'Sample - Superstore'!$V:$V,$A1766,'Sample - Superstore'!$N:$N,$B1766) -> 7.8555278
A1767: 2016-11 | B1767: TEC-AC-10002473 | C1767: Technology | D1767: Accessories | E1767: Maxell 4.7GB DVD-R | F1767: =SUMIFS('Sample - Superstore'!R:R,'Sample - Superstore'!$V:$V,$A1767,'Sample - Superstore'!$N:$N,$B1767) -> 76.661037 | G1767: =IF(OR($F1767<Lower_Limit,$F1767>Upper_Limit),TRUE,IF($F1767>Upper_percentile,"P99",IF($F1767<Lower_percentile,"P01",""))) | H1767: =SUMIFS('Sample - Superstore'!S:S,'Sample - Superstore'!$V:$V,$A1767,'Sample - Superstore'!$N:$N,$B1767) -> 3 | I1767: =SUMIFS('Sample - Superstore'!T:T,'Sample - Superstore'!$V:$V,$A1767,'Sample - Superstore'!$N:$N,$B1767) -> 0.2 | J1767: =SUMIFS('Sample - Superstore'!U:U,'Sample - Superstore'!$V:$V,$A1767,'Sample - Superstore'!$N:$N,$B1767) -> 20.123522
A1768: 2016-11 | B1768: OFF-AR-10000380 | C1768: Office Supplies | D1768: Art | E1768: Hunt PowerHouse Electric Pencil Sharpener, Blue | F1768: =SUMIFS('Sample - Superstore'!R:R,'Sample - Superstore'!$V:$V,$A1768,'Sample - Superstore'!$N:$N,$B1768) -> 85.556593 | G1768: =IF(OR($F1768<Lower_Limit,$F1768>Upper_Limit),TRUE,IF($F1768>Upper_percentile,"P99",IF($F1768<Lower_percentile,"P01",""))) | H1768: =SUMIFS('Sample - Superstore'!S:S,'Sample - Superstore'!$V:$V,$A1768,'Sample - Superstore'!$N:$N,$B1768) -> 2 | I1768: =SUMIFS('Sample - Superstore'!T:T,'Sample - Superstore'!$V:$V,$A1768,'Sample - Superstore'!$N:$N,$B1768) -> 0 | J1768: =SUMIFS('Sample - Superstore'!U:U,'Sample - Superstore'!$V:$V,$A1768,'Sample - Superstore'!$N:$N,$B1768) -> 25.666978
...

Sheet summary
A1: Month | B1: South | C1: West | D1: Central | E1: East
A2: 2016-01 | B2: =SUMIFS('Sample - Superstore'!$U:$U,'Sample - Superstore'!$V:$V,$A2,'Sample - Superstore'!$M:$M,B$1) -> 754.33702 | C2: =SUMIFS('Sample - Superstore'!$R:$R,'Sample - Superstore'!$V:$V,$A2,'Sample - Superstore'!$M:$M,C$1) -> 3657.822 | D2: =SUMIFS('Sample - Superstore'!$R:$R,'Sample - Superstore'!$V:$V,$A2,'Sample - Superstore'!$M:$M,D$1) -> 5975.4612 | E2: =SUMIFS('Sample - Superstore'!$R:$R,'Sample - Superstore'!$V:$V,$A2,'Sample - Superstore'!$M:$M,E$1) -> 4895.5019
A3: 2016-02 | B3: =SUMIFS('Sample - Superstore'!$R:$R,'Sample - Superstore'!$V:$V,$A3,'Sample - Superstore'!$M:$M,B$1) -> 3038.1588 | C3: =SUMIFS('Sample - Superstore'!$R:$R,'Sample - Superstore'!$V:$V,$A3,'Sample - Superstore'!$M:$M,C$1) -> 3100.162 | D3: =SUMIFS('Sample - Superstore'!$R:$R,'Sample - Superstore'!$V:$V,$A3,'Sample - Superstore'!$M:$M,D$1) -> 1137.0259 | E3: =SUMIFS('Sample - Superstore'!$R:$R,'Sample - Superstore'!$V:$V,$A3,'Sample - Superstore'!$M:$M,E$1) -> 3210.9663
A4: 2016-03 | B4: =SUMIFS('Sample - Superstore'!$R:$R,'Sample - Superstore'!$V:$V,$A4,'Sample - Superstore'!$M:$M,B$1) -> 3449.6369 | C4: =SUMIFS('Sample - Superstore'!$R:$R,'Sample - Superstore'!$V:$V,$A4,'Sample - Superstore'!$M:$M,C$1) -> 17559.031 | D4: =SUMIFS('Sample - Superstore'!$R:$R,'Sample - Superstore'!$V:$V,$A4,'Sample - Superstore'!$M:$M,D$1) -> 13538.036 | E4: =SUMIFS('Sample - Superstore'!$R:$R,'Sample - Superstore'!$V:$V,$A4,'Sample - Superstore'!$M:$M,E$1) -> 17241.851
A5: 2016-04 | B5: =SUMIFS('Sample - Superstore'!$R:$R,'Sample - Superstore'!$V:$V,$A5,'Sample - Superstore'!$M:$M,B$1) -> 2388.6562 | C5: =SUMIFS('Sample - Superstore'!$R:$R,'Sample - Superstore'!$V:$V,$A5,'Sample - Superstore'!$M:$M,C$1) -> 10482.009 | D5: =SUMIFS('Sample - Superstore'!$R:$R,'Sample - Superstore'!$V:$V,$A5,'Sample - Superstore'!$M:$M,D$1) -> 7775.5734 | E5: =SUMIFS('Sample - Superstore'!$R:$R,'Sample - Superstore'!$V:$V,$A5,'Sample - Superstore'!$M:$M,E$1) -> 18591.461
A6: 2016-05 | B6: =SUMIFS('Sample - Superstore'!$R:$R,'Sample - Superstore'!$V:$V,$A6,'Sample - Superstore'!$M:$M,B$1) -> 9452.7352 | C6: =SUMIFS('Sample - Superstore'!$R:$R,'Sample - Superstore'!$V:$V,$A6,'Sample - Superstore'!$M:$M,C$1) -> 10694.247 | D6: =SUMIFS('Sample - Superstore'!$R:$R,'Sample - Superstore'!$V:$V,$A6,'Sample - Superstore'!$M:$M,D$1) -> 12438.858 | E6: =SUMIFS('Sample - Superstore'!$R:$R,'Sample - Superstore'!$V:$V,$A6,'Sample - Superstore'!$M:$M,E$1) -> 23856.751
A7: 2016-06 | B7: =SUMIFS('Sample - Superstore'!$R:$R,'Sample - Superstore'!$V:$V,$A7,'Sample - Superstore'!$M:$M,B$1) -> 2712.2503 | C7: =SUMIFS('Sample - Superstore'!$R:$R,'Sample - Superstore'!$V:$V,$A7,'Sample - Superstore'!$M:$M,C$1) -> 18598.095 | D7: =SUMIFS('Sample - Superstore'!$R:$R,'Sample - Superstore'!$V:$V,$A7,'Sample - Superstore'!$M:$M,D$1) -> 7002.3688 | E7: =SUMIFS('Sample - Superstore'!$R:$R,'Sample - Superstore'!$V:$V,$A7,'Sample - Superstore'!$M:$M,E$1) -> 12542.246
A8: 2016-07 | B8: =SUMIFS('Sample - Superstore'!$R:$R,'Sample - Superstore'!$V:$V,$A8,'Sample - Superstore'!$M:$M,B$1) -> 5065.2552 | C8: =SUMIFS('Sample - Superstore'!$R:$R,'Sample - Superstore'!$V:$V,$A8,'Sample - Superstore'!$M:$M,C$1) -> 15280.883 | D8: =SUMIFS('Sample - Superstore'!$R:$R,'Sample - Superstore'!$V:$V,$A8,'Sample - Superstore'!$M:$M,D$1) -> 9630.3221 | E8: =SUMIFS('Sample - Superstore'!$R:$R,'Sample - Superstore'!$V:$V,$A8,'Sample - Superstore'!$M:$M,E$1) -> 9223.2423
A9: 2016-08 | B9: =SUMIFS('Sample - Superstore'!$R:$R,'Sample - Superstore'!$V:$V,$A9,'Sample - Superstore'!$M:$M,B$1) -> 2330.3828 | C9: =SUMIFS('Sample - Superstore'!$R:$R,'Sample - Superstore'!$V:$V,$A9,'Sample - Superstore'!$M:$M,C$1) -> 11817.852 | D9: =SUMIFS('Sample - Superstore'!$R:$R,'Sample - Superstore'!$V:$V,$A9,'Sample - Superstore'!$M:$M,D$1) -> 7649.8632 | E9: =SUMIFS('Sample - Superstore'!$R:$R,'Sample - Superstore'!$V:$V,$A9,'Sample - Superstore'!$M:$M,E$1) -> 10151.678
A10: 2016-09 | B10: =SUMIFS('Sample - Superstore'!$R:$R,'Sample - Superstore'!$V:$V,$A10,'Sample - Superstore'!$M:$M,B$1) -> 9087.5878 | C10: =SUMIFS('Sample - Superstore'!$R:$R,'Sample - Superstore'!$V:$V,$A10,'Sample - Superstore'!$M:$M,C$1) -> 23620.876 | D10: =SUMIFS('Sample - Superstore'!$R:$R,'Sample - Superstore'!$V:$V,$A10,'Sample - Superstore'!$M:$M,D$1) -> 19340.01 | E10: =SUMIFS('Sample - Superstore'!$R:$R,'Sample - Superstore'!$V:$V,$A10,'Sample - Superstore'!$M:$M,E$1) -> 22377.254
A11: 2016-10 | B11: =SUMIFS('Sample - Superstore'!$R:$R,'Sample - Superstore'!$V:$V,$A11,'Sample - Superstore'!$M:$M,B$1) -> 2345.8989 | C11: =SUMIFS('Sample - Superstore'!$R:$R,'Sample - Superstore'!$V:$V,$A11,'Sample - Superstore'!$M:$M,C$1) -> 15624.694 | D11: =SUMIFS('Sample - Superstore'!$R:$R,'Sample - Superstore'!$V:$V,$A11,'Sample - Superstore'!$M:$M,D$1) -> 28801.419 | E11: =SUMIFS('Sample - Superstore'!$R:$R,'Sample - Superstore'!$V:$V,$A11,'Sample - Superstore'!$M:$M,E$1) -> 16843.037
A12: 2016-11 | B12: =SUMIFS('Sample - Superstore'!$R:$R,'Sample - Superstore'!$V:$V,$A12,'Sample - Superstore'!$M:$M,B$1) -> 11441.488 | C12: =SUMIFS('Sample - Superstore'!$R:$R,'Sample - Superstore'!$V:$V,$A12,'Sample - Superstore'!$M:$M,C$1) -> 23923.005 | D12: =SUMIFS('Sample - Superstore'!$R:$R,'Sample - Superstore'!$V:$V,$A12,'Sample - Superstore'!$M:$M,D$1) -> 19140.532 | E12: =SUMIFS('Sample - Superstore'!$R:$R,'Sample - Superstore'!$V:$V,$A12,'Sample - Superstore'!$M:$M,E$1) -> 26019.631
A13: 2016-12 | B13: =SUMIFS('Sample - Superstore'!$R:$R,'Sample - Superstore'!$V:$V,$A13,'Sample - Superstore'!$M:$M,B$1) -> 7907.0045 | C13: =SUMIFS('Sample - Superstore'!$R:$R,'Sample - Superstore'!$V:$V,$A13,'Sample - Superstore'!$M:$M,C$1) -> 33121.5 | D13: =SUMIFS('Sample - Superstore'!$R:$R,'Sample - Superstore'!$V:$V,$A13,'Sample - Superstore'!$M:$M,D$1) -> 28964.437 | E13: =SUMIFS('Sample - Superstore'!$R:$R,'Sample - Superstore'!$V:$V,$A13,'Sample - Superstore'!$M:$M,E$1) -> 31593.103
A14: 2017-01 | B14: =SUMIFS('Sample - Superstore'!$R:$R,'Sample - Superstore'!$V:$V,$A14,'Sample - Superstore'!$M:$M,B$1) -> 3437.9625 | C14: =SUMIFS('Sample - Superstore'!$R:$R,'Sample - Superstore'!$V:$V,$A14,'Sample - Superstore'!$M:$M,C$1) -> 12081.844 | D14: =SUMIFS('Sample - Superstore'!$R:$R,'Sample - Superstore'!$V:$V,$A14,'Sample - Superstore'!$M:$M,D$1) -> 25079.537 | E14: =SUMIFS('Sample - Superstore'!$R:$R,'Sample - Superstore'!$V:$V,$A14,'Sample - Superstore'!$M:$M,E$1) -> 6231.9023
... A25: 2017-12 | B25: =SUMIFS('Sample - Superstore'!$R:$R,'Sample - Superstore'!$V:$V,$A25,'Sample - Superstore'!$M:$M,B$1) -> 9185.7199 | C25: =SUMIFS('Sample - Superstore'!$R:$R,'Sample - Superstore'!$V:$V,$A25,'Sample - Superstore'!$M:$M,C$1) -> 29652.095 | D25: =SUMIFS('Sample - Superstore'!$R:$R,'Sample - Superstore'!$V:$V,$A25,'Sample - Superstore'!$M:$M,D$1) -> 24412.843 | E25: =SUMIFS('Sample - Superstore'!$R:$R,'Sample - Superstore'!$V:$V,$A25,'Sample - Superstore'!$M:$M,E$1) -> 35582.514

Sheet dinámica
